Workbook

Sheet Read Me
B2: Lab-2: SDLC Model Selection — Team T6 (Micro-lending / SHG Credit Management System)
B4: Contents
B5: 1. System Profile & Criteria Weights
B6: 2. Decision Matrix (M4) — 11 criteria x 7 SDLC models, weighted scoring
B7: 3. Ranking (M5) — computed ranking with normalized percentage fit
B8: 4. Sensitivity Analysis (M6) — three +-5 point weight-shift scenarios
B10: Convention: blue text = hard-coded expert-judgment input (weights, 1-5 scores). Black text = formula. Green fill = current winner.

Sheet Criteria_Weights
A1: M2/M3 — Decision Criteria and Weights (Team T6: Micro-lending / SHG Credit Management System)
A3: Code | B3: Criterion | C3: Weight (%) | D3: Justification
A4: C1 | B4: Requirements volatility | C4: 8 | D4: Core SHG lending workflow is well established, but interest/subsidy rules and RBI/NABARD formats change periodically -> moderate, not top, weight.
A5: C2 | B5: Project size | C5: 8 | D5: Medium-large system: onboarding/KYC, appraisal, disbursement, ledger, NPA tracking, MIS reporting, notifications.
A6: C3 | B6: Team distribution | C6: 4 | D6: Small, largely co-located implementing team with occasional remote field-office coordination -> low weight.
A7: C4 | B7: Risk exposure | C7: 14 | D7: Errors in interest/principal computation or authorization bypass cause direct financial loss to vulnerable borrowers.
A8: C5 | B8: Regulatory burden | C8: 14 | D8: Must comply with RBI NBFC-MFI Master Directions, interest-rate/pricing disclosure norms, KYC/AML (PMLA), NABARD reporting.
A9: C6 | B9: Customer availability | C9: 6 | D9: Branch/loan officers and SHG federation staff available periodically (not continuously); rural connectivity limits engagement.
A10: C7 | B10: Contract type | C10: 4 | D10: Assumed fixed-scope, institution-funded internal project tied to a financial-year cycle, not a flexible T&M contract.
A11: C8 | B11: Delivery urgency | C11: 8 | D11: Go-live tied to a lending-cycle/financial-year milestone; important but not an emergency deployment.
A12: C9 | B12: Defect tolerance | C12: 14 | D12: Ledger/interest errors are financially and legally unacceptable; system must be auditable to the rupee.
A13: C10 | B13: Security & fraud-resistance (added) | C13: 12 | D13: Added: financial system moving money and PII needs explicit evaluation of built-in security/fraud-resistance, distinct from generic risk.
A14: C11 | B14: Auditability & regulatory traceability (added) | C14: 8 | D14: Added: RBI/NABARD compliance demands requirement-to-test traceability that generic 'risk' or 'regulatory burden' rows do not fully capture.
B15: TOTAL | C15: =SUM(C4:C14) -> 100

Sheet Decision_Matrix
A1: M4 — Seven-Model Weighted Decision Matrix (1=Very poor fit ... 5=Excellent fit)
A3: Code | B3: Criterion | C3: Weight (%) | D3: Waterfall | E3: Incremental | F3: Prototyping | G3: Spiral | H3: V-Model | I3: Component-Based | J3: Scrum | L3: Scoring rationale (applies across the row)
A4: C1 | B4: Requirements volatility | C4: =Criteria_Weights!C4 -> 8 | D4: 2 | E4: 4 | F4: 5 | G4: 4 | H4: 2 | I4: 3 | J4: 5 | L4: Rigid models (Waterfall, V-Model) score low on volatility-handling; Prototyping/Scrum score high; Incremental/Spiral moderate-high.
A5: C2 | B5: Project size | C5: =Criteria_Weights!C5 -> 8 | D5: 4 | E5: 5 | F5: 2 | G5: 4 | H5: 4 | I5: 4 | J5: 3 | L5: Incremental, V-Model, Spiral, CBD suit medium-large structured systems well; Prototyping is weak at this scale; Scrum needs scaling effort.
A6: C3 | B6: Team distribution | C6: =Criteria_Weights!C6 -> 4 | D6: 4 | E6: 4 | F6: 3 | G6: 3 | H6: 4 | I6: 5 | J6: 3 | L6: Documentation-heavy (Waterfall, V-Model) and component-based work travel well across sites; Scrum/Prototyping prefer tight co-location.
A7: C4 | B7: Risk exposure | C7: =Criteria_Weights!C7 -> 14 | D7: 2 | E7: 3 | F7: 3 | G7: 5 | H7: 4 | I7: 3 | J7: 3 | L7: Spiral is explicitly risk-driven (highest); V-Model's rigorous V&V reduces defect-risk; Waterfall has no formal risk step.
A8: C5 | B8: Regulatory burden | C8: =Criteria_Weights!C8 -> 14 | D8: 4 | E8: 3 | F8: 2 | G8: 3 | H8: 5 | I8: 3 | J8: 2 | L8: V-Model's requirement-to-test mapping best satisfies regulators; Waterfall's phase documents also help; Scrum/Prototyping are weakest.
A9: C6 | B9: Customer availability | C9: =Criteria_Weights!C9 -> 6 | D9: 4 | E9: 3 | F9: 2 | G9: 4 | H9: 4 | I9: 4 | J9: 2 | L9: Waterfall/V-Model/CBD need customers mainly at defined milestones (fits periodic availability); Scrum's frequent ceremonies exceed it.
A10: C7 | B10: Contract type | C10: =Criteria_Weights!C10 -> 4 | D10: 5 | E10: 4 | F10: 2 | G10: 3 | H10: 5 | I10: 4 | J10: 2 | L10: Waterfall and V-Model fit fixed-scope funding naturally; Scrum and Prototyping assume flexible scope/cost.
A11: C8 | B11: Delivery urgency | C11: =Criteria_Weights!C11 -> 8 | D11: 2 | E11: 4 | F11: 3 | G11: 3 | H11: 2 | I11: 4 | J11: 4 | L11: Incremental, CBD and Scrum release usable subsets early; Waterfall and V-Model are slower to first release.
A12: C9 | B12: Defect tolerance | C12: =Criteria_Weights!C12 -> 14 | D12: 3 | E12: 4 | F12: 2 | G12: 3 | H12: 5 | I12: 3 | J12: 3 | L12: V-Model's per-phase verification gives the strongest near-zero-defect guarantee; Prototyping risks carrying prototype defects forward.
A13: C10 | B13: Security & fraud-resistance (added) | C13: =Criteria_Weights!C13 -> 12 | D13: 3 | E13: 3 | F13: 2 | G13: 4 | H13: 4 | I13: 3 | J13: 2 | L13: Spiral's risk cycles and V-Model's systematic verification build in security best; Prototyping and Scrum treat it ad hoc by default.
A14: C11 | B14: Auditability & regulatory traceability (added) | C14: =Criteria_Weights!C14 -> 8 | D14: 4 | E14: 3 | F14: 2 | G14: 3 | H14: 5 | I14: 3 | J14: 2 | L14: V-Model gives direct requirement-to-test traceability (best); Waterfall/Spiral document well; Scrum/Prototyping trace poorly by default.
B15: Weighted Total (out of 5) | D15: =SUMPRODUCT($C$4:$C$14/100,D4:D14) -> 3.18 | E15: =SUMPRODUCT($C$4:$C$14/100,E4:E14) -> 3.54 | F15: =SUMPRODUCT($C$4:$C$14/100,F4:F14) -> 2.5 | G15: =SUMPRODUCT($C$4:$C$14/100,G4:G14) -> 3.62 | H15: =SUMPRODUCT($C$4:$C$14/100,H4:H14) -> 4.08 | I15: =SUMPRODUCT($C$4:$C$14/100,I4:I14) -> 3.34 | J15: =SUMPRODUCT($C$4:$C$14/100,J4:J14) -> 2.8
B16: Normalized Fit (%) | D16: =D15/5 -> 0.636 | E16: =E15/5 -> 0.708 | F16: =F15/5 -> 0.5 | G16: =G15/5 -> 0.724 | H16: =H15/5 -> 0.816 | I16: =I15/5 -> 0.668 | J16: =J15/5 -> 0.56
B17: Rank | D17: =RANK(D15,D15:J15,0) -> 5 | E17: =RANK(E15,D15:J15,0) -> 3 | F17: =RANK(F15,D15:J15,0) -> 7 | G17: =RANK(G15,D15:J15,0) -> 2 | H17: =RANK(H15,D15:J15,0) -> 1 | I17: =RANK(I15,D15:J15,0) -> 4 | J17: =RANK(J15,D15:J15,0) -> 6

Sheet Ranking
A1: M5 — Ranking and Recommendation
A3: Rank | B3: SDLC Model | C3: Weighted Score (/5) | D3: Normalized Fit (%)
A4: 1 | B4: =INDEX($A$13:$A$19,MATCH(C4,$B$13:$B$19,0)) -> V-Model | C4: =LARGE($B$13:$B$19,1) -> 4.08 | D4: =C4/5 -> 0.816
A5: 2 | B5: =INDEX($A$13:$A$19,MATCH(C5,$B$13:$B$19,0)) -> Spiral | C5: =LARGE($B$13:$B$19,2) -> 3.62 | D5: =C5/5 -> 0.724
A6: 3 | B6: =INDEX($A$13:$A$19,MATCH(C6,$B$13:$B$19,0)) -> Incremental | C6: =LARGE($B$13:$B$19,3) -> 3.54 | D6: =C6/5 -> 0.708
A7: 4 | B7: =INDEX($A$13:$A$19,MATCH(C7,$B$13:$B$19,0)) -> Component-Based | C7: =LARGE($B$13:$B$19,4) -> 3.34 | D7: =C7/5 -> 0.668
A8: 5 | B8: =INDEX($A$13:$A$19,MATCH(C8,$B$13:$B$19,0)) -> Waterfall | C8: =LARGE($B$13:$B$19,5) -> 3.18 | D8: =C8/5 -> 0.636
A9: 6 | B9: =INDEX($A$13:$A$19,MATCH(C9,$B$13:$B$19,0)) -> Scrum | C9: =LARGE($B$13:$B$19,6) -> 2.8 | D9: =C9/5 -> 0.56
A10: 7 | B10: =INDEX($A$13:$A$19,MATCH(C10,$B$13:$B$19,0)) -> Prototyping | C10: =LARGE($B$13:$B$19,7) -> 2.5 | D10: =C10/5 -> 0.5
A12: Winner outperforms runner-up chiefly on the three highest-weight regulatory/quality criteria: C5 Regulatory burden (14%), C9 Defect tolerance (14%) and C11 Auditability & traceability (8%), where V-Model scores the maximum 5/5 while the runner-up (Spiral) scores only 3/5 on each.
A13: Waterfall | B13: =Decision_Matrix!D15 -> 3.18
A14: Incremental | B14: =Decision_Matrix!E15 -> 3.54
A15: Prototyping | B15: =Decision_Matrix!F15 -> 2.5
A16: Spiral | B16: =Decision_Matrix!G15 -> 3.62
A17: V-Model | B17: =Decision_Matrix!H15 -> 4.08
A18: Component-Based | B18: =Decision_Matrix!I15 -> 3.34
A19: Scrum | B19: =Decision_Matrix!J15 -> 2.8

Sheet Sensitivity_Analysis
A1: M6 — Sensitivity Analysis (each scenario shifts one weight by +5 and another by -5; total stays 100)
A3: Scenario 1: Risk exposure (C4) +5, Security & fraud-resistance (C10) -5
A4: Code | B4: Criterion | C4: Original Wt. | D4: New Wt.
A5: C1 | B5: Requirements volatility | C5: =Criteria_Weights!C4 -> 8 | D5: =C5 -> 8
A6: C2 | B6: Project size | C6: =Criteria_Weights!C5 -> 8 | D6: =C6 -> 8
A7: C3 | B7: Team distribution | C7: =Criteria_Weights!C6 -> 4 | D7: =C7 -> 4
A8: C4 | B8: Risk exposure | C8: =Criteria_Weights!C7 -> 14 | D8: =C8+5 -> 19
A9: C5 | B9: Regulatory burden | C9: =Criteria_Weights!C8 -> 14 | D9: =C9 -> 14
A10: C6 | B10: Customer availability | C10: =Criteria_Weights!C9 -> 6 | D10: =C10 -> 6
A11: C7 | B11: Contract type | C11: =Criteria_Weights!C10 -> 4 | D11: =C11 -> 4
A12: C8 | B12: Delivery urgency | C12: =Criteria_Weights!C11 -> 8 | D12: =C12 -> 8
A13: C9 | B13: Defect tolerance | C13: =Criteria_Weights!C12 -> 14 | D13: =C13 -> 14
A14: C10 | B14: Security & fraud-resistance (added) | C14: =Criteria_Weights!C13 -> 12 | D14: =C14-5 -> 7
A15: C11 | B15: Auditability & regulatory traceability (added) | C15: =Criteria_Weights!C14 -> 8 | D15: =C15 -> 8
B16: Total (must = 100) | D16: =SUM(D5:D15) -> 100
A18: Recomputed weighted score per model:
A19: Waterfall | B19: Incremental | C19: Prototyping | D19: Spiral | E19: V-Model | F19: Component-Based | G19: Scrum
A20: =SUMPRODUCT($D$5:$D$15/100,Decision_Matrix!D4:D14) -> 3.13 | B20: =SUMPRODUCT($D$5:$D$15/100,Decision_Matrix!E4:E14) -> 3.54 | C20: =SUMPRODUCT($D$5:$D$15/100,Decision_Matrix!F4:F14) -> 2.55 | D20: =SUMPRODUCT($D$5:$D$15/100,Decision_Matrix!G4:G14) -> 3.67 | E20: =SUMPRODUCT($D$5:$D$15/100,Decision_Matrix!H4:H14) -> 4.08 | F20: =SUMPRODUCT($D$5:$D$15/100,Decision_Matrix!I4:I14) -> 3.34 | G20: =SUMPRODUCT($D$5:$D$15/100,Decision_Matrix!J4:J14) -> 2.85
A21: New winner: | B21: =INDEX(A19:G19,MATCH(MAX(A20:G20),A20:G20,0)) -> V-Model
A23: Scenario 2: Regulatory burden (C5) +5, Customer availability (C6) -5
A24: Code | B24: Criterion | C24: Original Wt. | D24: New Wt.
A25: C1 | B25: Requirements volatility | C25: =Criteria_Weights!C4 -> 8 | D25: =C25 -> 8
A26: C2 | B26: Project size | C26: =Criteria_Weights!C5 -> 8 | D26: =C26 -> 8
A27: C3 | B27: Team distribution | C27: =Criteria_Weights!C6 -> 4 | D27: =C27 -> 4
A28: C4 | B28: Risk exposure | C28: =Criteria_Weights!C7 -> 14 | D28: =C28 -> 14
A29: C5 | B29: Regulatory burden | C29: =Criteria_Weights!C8 -> 14 | D29: =C29+5 -> 19
A30: C6 | B30: Customer availability | C30: =Criteria_Weights!C9 -> 6 | D30: =C30-5 -> 1
A31: C7 | B31: Contract type | C31: =Criteria_Weights!C10 -> 4 | D31: =C31 -> 4
A32: C8 | B32: Delivery urgency | C32: =Criteria_Weights!C11 -> 8 | D32: =C32 -> 8
A33: C9 | B33: Defect tolerance | C33: =Criteria_Weights!C12 -> 14 | D33: =C33 -> 14
A34: C10 | B34: Security & fraud-resistance (added) | C34: =Criteria_Weights!C13 -> 12 | D34: =C34 -> 12
A35: C11 | B35: Auditability & regulatory traceability (added) | C35: =Criteria_Weights!C14 -> 8 | D35: =C35 -> 8
B36: Total (must = 100) | D36: =SUM(D25:D35) -> 100
A38: Recomputed weighted score per model:
A39: Waterfall | B39: Incremental | C39: Prototyping | D39: Spiral | E39: V-Model | F39: Component-Based | G39: Scrum
A40: =SUMPRODUCT($D$25:$D$35/100,Decision_Matrix!D4:D14) -> 3.18 | B40: =SUMPRODUCT($D$25:$D$35/100,Decision_Matrix!E4:E14) -> 3.54 | C40: =SUMPRODUCT($D$25:$D$35/100,Decision_Matrix!F4:F14) -> 2.5 | D40: =SUMPRODUCT($D$25:$D$35/100,Decision_Matrix!G4:G14) -> 3.57 | E40: =SUMPRODUCT($D$25:$D$35/100,Decision_Matrix!H4:H14) -> 4.13 | F40: =SUMPRODUCT($D$25:$D$35/100,Decision_Matrix!I4:I14) -> 3.29 | G40: =SUMPRODUCT($D$25:$D$35/100,Decision_Matrix!J4:J14) -> 2.8
A41: New winner: | B41: =INDEX(A39:G39,MATCH(MAX(A40:G40),A40:G40,0)) -> V-Model
A43: Scenario 3 (adverse test): Defect tolerance (C9) -5, Requirements volatility (C1) +5
A44: Code | B44: Criterion | C44: Original Wt. | D44: New Wt.
A45: C1 | B45: Requirements volatility | C45: =Criteria_Weights!C4 -> 8 | D45: =C45+5 -> 13
...
